Workbook

Sheet Pricelist Lengkap
F1: NON BUNDLING | H1: BUNDLING SEMEN
A2: BRAND | B2: PROVINSI | C2: REGION | D2: KECAMATAN KHUSUS | E2: KABUPATEN | F2: FRANCO CD (Tebal 10) | G2: FRANCO TRONTON (Tebal 10) | H2: FRANCO CD (Tebal 10) | I2: FRANCO TRONTON (Tebal 10) | J2: List Pick
A3: BLESSCON | B3: JAWA TIMUR | C3: SURABAYA | E3: SURABAYA | F3: 670000 | G3: 630000 | H3: 690000 | I3: 635000 | J3: =E3 -> SURABAYA
A4: BLESSCON | B4: JAWA TIMUR | C4: SURABAYA | E4: GRESIK | F4: 670000 | G4: 630000 | H4: 690000 | I4: 635000 | J4: =E4 -> GRESIK
A5: BLESSCON | B5: JAWA TIMUR | C5: SURABAYA | E5: SIDOARJO | F5: 660000 | G5: 630000 | H5: 680000 | I5: 635000 | J5: =E5 -> SIDOARJO
A6: BLESSCON | B6: JAWA TIMUR | C6: BANYUWANGI | E6: BANYUWANGI | F6: 770000 | G6: 700000 | H6: 790000 | I6: 705000 | J6: =E6 -> BANYUWANGI
A7: BLESSCON | B7: JAWA TIMUR | C7: JEMBER | E7: BONDOWOSO | F7: 700000 | G7: 670000 | H7: 720000 | I7: 675000 | J7: =E7 -> BONDOWOSO
A8: BLESSCON | B8: JAWA TIMUR | C8: JEMBER | E8: JEMBER | F8: 690000 | G8: 670000 | H8: 710000 | I8: 675000 | J8: =E8 -> JEMBER
A9: BLESSCON | B9: JAWA TIMUR | C9: JEMBER | E9: SITUBONDO | F9: 695000 | G9: 670000 | H9: 715000 | I9: 675000 | J9: =E9 -> SITUBONDO
A10: BLESSCON | B10: JAWA TIMUR | C10: LAMONGAN | E10: LAMONGAN | F10: 690000 | G10: 640000 | H10: 710000 | I10: 645000 | J10: =E10 -> LAMONGAN
A11: BLESSCON | B11: JAWA TIMUR | C11: PASURUAN | E11: PASURUAN | F11: 605000 | G11: 590000 | H11: 625000 | I11: 595000 | J11: =E11 -> PASURUAN
A12: BLESSCON | B12: JAWA TIMUR | C12: MADURA | E12: BANGKALAN | F12: 700000 | G12: 645000 | H12: 720000 | I12: 650000 | J12: =E12 -> BANGKALAN
A13: BLESSCON | B13: JAWA TIMUR | C13: MADURA | E13: SAMPANG | F13: 720000 | G13: 665000 | H13: 740000 | I13: 670000 | J13: =E13 -> SAMPANG
A14: BLESSCON | B14: JAWA TIMUR | C14: MADURA | E14: PAMEKASAN | F14: 730000 | G14: 675000 | H14: 750000 | I14: 680000 | J14: =E14 -> PAMEKASAN
... A32: BLESSCON | B32: JAWA TIMUR | C32: MALANG | E32: MALANG 1 | F32: 660000 | G32: 640000 | H32: 680000 | I32: 645000 | J32: =E32 -> MALANG 1
A33: BLESSCON | B33: JAWA TIMUR | C33: MALANG | D33: WAJAK, TUREN, GONDANGLEGI, WONOSARI, NGAJUNG(NGANJUM), SUMBERPUCUNG, KEPANJEN | E33: MALANG 2 | F33: 660000 | G33: 640000 | H33: 680000 | I33: 645000 | J33: =E33 -> MALANG 2
A34: BLESSCON | B34: JAWA TIMUR | C34: MALANG | D34: KOREMENGAN, PAGELARAN, GEDANGAN, KALIPARE, DAMPIT, TIRTOYUDO, AMPELGADING, SUMBERMANJINGWETAN, BANTUR, PAGAK, DONOMULYO | E34: MALANG 3 | F34: 670000 | G34: 640000 | H34: 690000 | I34: 645000 | J34: =E34 -> MALANG 3
A35: BLESSCON | B35: JAWA TENGAH | C35: YOGYAKARTA | E35: BANTUL | F35: 730000 | G35: 690000 | H35: 750000 | I35: 695000 | J35: =E35 -> BANTUL
A36: BLESSCON | B36: JAWA TENGAH | C36: YOGYAKARTA | E36: GUNUNG KIDUL | F36: 730000 | G36: 690000 | H36: 750000 | I36: 695000 | J36: =E36 -> GUNUNG KIDUL
A37: BLESSCON | B37: JAWA TENGAH | C37: YOGYAKARTA | E37: KULON PROGO | F37: 730000 | G37: 690000 | H37: 750000 | I37: 695000 | J37: =E37 -> KULON PROGO
A38: BLESSCON | B38: JAWA TENGAH | C38: YOGYAKARTA | E38: SLEMAN | F38: 730000 | G38: 690000 | H38: 750000 | I38: 695000 | J38: =E38 -> SLEMAN
A39: BLESSCON | B39: JAWA TENGAH | C39: YOGYAKARTA | E39: YOGYAKARTA | F39: 730000 | G39: 690000 | H39: 750000 | I39: 695000 | J39: =E39 -> YOGYAKARTA
A40: BLESSCON | B40: JAWA TENGAH | C40: BANYUMAS | E40: BANJARNEGARA | F40: 660000 | G40: 620000 | H40: 680000 | I40: 625000 | J40: =E40 -> BANJARNEGARA
A41: BLESSCON | B41: JAWA TENGAH | C41: BANYUMAS | E41: BANYUMAS | F41: 660000 | G41: 620000 | H41: 680000 | I41: 625000 | J41: =E41 -> BANYUMAS
A42: BLESSCON | B42: JAWA TENGAH | C42: BANYUMAS | E42: CILACAP | F42: 660000 | G42: 620000 | H42: 680000 | I42: 625000 | J42: =E42 -> CILACAP
A43: BLESSCON | B43: JAWA TENGAH | C43: BANYUMAS | E43: PURBALINGGA | F43: 660000 | G43: 620000 | H43: 680000 | I43: 625000 | J43: =E43 -> PURBALINGGA
A44: BLESSCON | B44: JAWA TENGAH | C44: KEDU | E44: MAGELANG | F44: 700000 | G44: 660000 | H44: 720000 | I44: 665000 | J44: =E44 -> MAGELANG
A45: BLESSCON | B45: JAWA TENGAH | C45: KEDU | E45: PURWOREJO | F45: 680000 | G45: 640000 | H45: 700000 | I45: 645000 | J45: =E45 -> PURWOREJO
A46: BLESSCON | B46: JAWA TENGAH | C46: KEDU | E46: KEBUMEN | F46: 660000 | G46: 620000 | H46: 680000 | I46: 625000 | J46: =E46 -> KEBUMEN
... A105: SUPERIOR | B105: JAWA TIMUR | C105: MALANG | E105: MALANG 1 | F105: 715000 | G105: 670000 | H105: 735000 | I105: 675000 | J105: =E105 -> MALANG 1
A106: SUPERIOR | B106: JAWA TIMUR | C106: MALANG | D106: WAJAK, TUREN, GONDANGLEGI, WONOSARI, NGAJUNG(NGANJUM), SUMBERPUCUNG, KEPANJEN | E106: MALANG 2 | F106: 715000 | G106: 665000 | H106: 735000 | I106: 670000 | J106: =E106 -> MALANG 2
A107: SUPERIOR | B107: JAWA TIMUR | C107: MALANG | D107: KOREMENGAN, PAGELARAN, GEDANGAN, KALIPARE, DAMPIT, TIRTOYUDO, AMPELGADING, SUMBERMANJINGWETAN, BANTUR, PAGAK, DONOMULYO | E107: MALANG 3 | F107: 725000 | G107: 670000 | H107: 745000 | I107: 675000 | J107: =E107 -> MALANG 3
A108: SUPERIOR | B108: JAWA TENGAH | C108: YOGYAKARTA | E108: BANTUL | F108: 740000 | G108: 700000 | H108: 760000 | I108: 705000 | J108: =E108 -> BANTUL
A109: SUPERIOR | B109: JAWA TENGAH | C109: YOGYAKARTA | E109: GUNUNG KIDUL | F109: 740000 | G109: 700000 | H109: 760000 | I109: 705000 | J109: =E109 -> GUNUNG KIDUL
A110: SUPERIOR | B110: JAWA TENGAH | C110: YOGYAKARTA | E110: KULON PROGO | F110: 740000 | G110: 700000 | H110: 760000 | I110: 705000 | J110: =E110 -> KULON PROGO
A111: SUPERIOR | B111: JAWA TENGAH | C111: YOGYAKARTA | E111: SLEMAN | F111: 740000 | G111: 700000 | H111: 760000 | I111: 705000 | J111: =E111 -> SLEMAN
A112: SUPERIOR | B112: JAWA TENGAH | C112: YOGYAKARTA | E112: YOGYAKARTA | F112: 740000 | G112: 700000 | H112: 760000 | I112: 705000 | J112: =E112 -> YOGYAKARTA
A113: SUPERIOR | B113: JAWA TENGAH | C113: BANYUMAS | E113: BANJARNEGARA | F113: 780000 | G113: 710000 | H113: 800000 | I113: 715000 | J113: =E113 -> BANJARNEGARA
A114: SUPERIOR | B114: JAWA TENGAH | C114: BANYUMAS | E114: BANYUMAS | F114: 790000 | G114: 675000 | H114: 810000 | I114: 680000 | J114: =E114 -> BANYUMAS
A115: SUPERIOR | B115: JAWA TENGAH | C115: BANYUMAS | E115: CILACAP | F115: 765000 | G115: 670000 | H115: 785000 | I115: 675000 | J115: =E115 -> CILACAP
...

Sheet Search Harga
C3: SILAHKAN DI PICK | H3: SILAHKAN DI PICK
B5: JAWA TIMUR - NON BUNDLING | G5: JAWA TIMUR - BUNDLING SEMEN 10 SAK
B6: BRAND | C6: KABUPATEN | D6: HARGA FRANCO COLT DIESEL | E6: HARGA FRANCO TRONTON | G6: BRAND | H6: KABUPATEN | I6: HARGA FRANCO COLT DIESEL | J6: HARGA FRANCO TRONTON
B7: BLESSCON | C7: BALI | D7: =SUMIFS('Pricelist Lengkap'!$F:$F,'Pricelist Lengkap'!$E:$E,'Search Harga'!$C7,'Pricelist Lengkap'!$A:$A,'Search Harga'!$B7) -> 0 | E7: =SUMIFS('Pricelist Lengkap'!$G:$G,'Pricelist Lengkap'!$E:$E,'Search Harga'!$C7,'Pricelist Lengkap'!$A:$A,'Search Harga'!$B7) -> 790000 | G7: BLESSCON | H7: BANYUWANGI | I7: =SUMIFS('Pricelist Lengkap'!$H:$H,'Pricelist Lengkap'!$E:$E,'Search Harga'!$H7,'Pricelist Lengkap'!$A:$A,'Search Harga'!$G7) -> 790000 | J7: =SUMIFS('Pricelist Lengkap'!$I:$I,'Pricelist Lengkap'!$E:$E,'Search Harga'!$H7,'Pricelist Lengkap'!$A:$A,'Search Harga'!$G7) -> 705000
B9: JAWA TENGAH - NON BUNDLING | G9: JAWA TENGAH - BUNDLING SEMEN 10 SAK
B10: BRAND | C10: KABUPATEN | D10: HARGA FRANCO COLT DIESEL | E10: HARGA FRANCO TRONTON | G10: BRAND | H10: KABUPATEN | I10: HARGA FRANCO COLT DIESEL | J10: HARGA FRANCO TRONTON
B11: SUPERIOR | C11: BALI | D11: =SUMIFS('Pricelist Lengkap'!$F:$F,'Pricelist Lengkap'!$E:$E,'Search Harga'!$C11,'Pricelist Lengkap'!$A:$A,'Search Harga'!$B11) -> 0 | E11: =SUMIFS('Pricelist Lengkap'!$G:$G,'Pricelist Lengkap'!$E:$E,'Search Harga'!$C11,'Pricelist Lengkap'!$A:$A,'Search Harga'!$B11) -> 785000 | G11: SUPERIOR | H11: BANYUWANGI | I11: =SUMIFS('Pricelist Lengkap'!$H:$H,'Pricelist Lengkap'!$E:$E,'Search Harga'!$H11,'Pricelist Lengkap'!$A:$A,'Search Harga'!$G11) -> 860000 | J11: =SUMIFS('Pricelist Lengkap'!$I:$I,'Pricelist Lengkap'!$E:$E,'Search Harga'!$H11,'Pricelist Lengkap'!$A:$A,'Search Harga'!$G11) -> 745000
